Workbook

Sheet Ranking Temporada
A1: Deck con mayor Win% de la temporada | J1: Mayor asistencia mensual | O1: Representacion de sets
A2: El minimo de partidas para que un deck entre a la lista es 10. Se aplica
A3: Set | B3: Deck | C3: Partidas Jugadas | D3: Wilson Score | E3: Win % | F3: Carta 1 | G3: Carta 2 | H3: Carta 3 | J3: Jugador | K3: Partidas | L3: Sets diferentes | M3: Signature | O3: Set | P3: Partidas | Q3: Jugadores | R3: Imagen
A4: =IFERROR(__xludf.DUMMYFUNCTION("QUERY( Set_Stats!E4:K1000, ""SELECT Col1,Col2,Col6,Col7,Col5 WHERE Col6 >= 10 AND Col1 <> '?' AND Col2 <> '?' ORDER BY Col7 DESC"", 0 )"),"OSK") -> OSK | B4: =IFERROR(__xludf.DUMMYFUNCTION("""COMPUTED_VALUE"""),"Door Pants") -> Door Pants | C4: =IFERROR(__xludf.DUMMYFUNCTION("""COMPUTED_VALUE"""),31.0) -> 31 | D4: =IFERROR(__xludf.DUMMYFUNCTION("""COMPUTED_VALUE"""),0.501406855599508) -> 0.50140686 | E4: =IFERROR(__xludf.DUMMYFUNCTION("""COMPUTED_VALUE"""),0.6774193548387096) -> 0.67741935 | F4: =IFERROR(__xludf.DUMMYFUNCTION("IF(A4="""","""",IMAGE(QUERY('Deck Info'!A:F,""SELECT D WHERE A = '""&A4&""' AND B = '""&B4&""'"")))"),"") | G4: =IFERROR(__xludf.DUMMYFUNCTION("IF(A4="""","""",IMAGE(QUERY('Deck Info'!A:F,""SELECT E WHERE A = '""&A4&""' AND B = '""&B4&""'"")))"),"") | H4: =IFERROR(__xludf.DUMMYFUNCTION("IF(A4="""","""",IMAGE(QUERY('Deck Info'!A:F,""SELECT F WHERE A = '""&A4&""' AND B = '""&B4&""'"")))"),"") | J4: =IFERROR(__xludf.DUMMYFUNCTION("QUERY( 'Raw Data'!N:S, ""SELECT Col1,Col2,Col6 ORDER BY Col2 DESC LIMIT 20"", 0 )"),"Kartoffel") -> Kartoffel | K4: =IFERROR(__xludf.DUMMYFUNCTION("""COMPUTED_VALUE"""),30.0) -> 30 | L4: =IFERROR(__xludf.DUMMYFUNCTION("""COMPUTED_VALUE"""),3.0) -> 3 | M4: =IFERROR(__xludf.DUMMYFUNCTION("IMAGE(QUERY('Player Refs'!A:B,""SELECT B WHERE A = '""&J4&""'"",0))"),"") | O4: =IFERROR(__xludf.DUMMYFUNCTION("QUERY( Set_Stats!A:C, ""SELECT A,B,C WHERE A IS NOT NULL ORDER BY B DESC LIMIT 10"", 0 )"),"?") -> ? | P4: =IFERROR(__xludf.DUMMYFUNCTION("""COMPUTED_VALUE"""),87.0) -> 87 | Q4: =IFERROR(__xludf.DUMMYFUNCTION("""COMPUTED_VALUE"""),15.0) -> 15 | R4: =IFERROR(__xludf.DUMMYFUNCTION("IMAGE(QUERY('Set Refs'!A:B,""SELECT B WHERE A = '""&O4&""'"",0))"),"")
A5: =IFERROR(__xludf.DUMMYFUNCTION("""COMPUTED_VALUE"""),"EIS") -> EIS | B5: =IFERROR(__xludf.DUMMYFUNCTION("""COMPUTED_VALUE"""),"8 Door TD") -> 8 Door TD | C5: =IFERROR(__xludf.DUMMYFUNCTION("""COMPUTED_VALUE"""),12.0) -> 12 | D5: =IFERROR(__xludf.DUMMYFUNCTION("""COMPUTED_VALUE"""),0.4676896608793401) -> 0.46768966 | E5: =IFERROR(__xludf.DUMMYFUNCTION("""COMPUTED_VALUE"""),0.75) -> 0.75 | F5: =IFERROR(__xludf.DUMMYFUNCTION("IF(A5="""","""",IMAGE(QUERY('Deck Info'!A:F,""SELECT D WHERE A = '""&A5&""' AND B = '""&B5&""'"")))"),"") | G5: =IFERROR(__xludf.DUMMYFUNCTION("IF(A5="""","""",IMAGE(QUERY('Deck Info'!A:F,""SELECT E WHERE A = '""&A5&""' AND B = '""&B5&""'"")))"),"") | H5: =IFERROR(__xludf.DUMMYFUNCTION("IF(A5="""","""",IMAGE(QUERY('Deck Info'!A:F,""SELECT F WHERE A = '""&A5&""' AND B = '""&B5&""'"")))"),"") | J5: =IFERROR(__xludf.DUMMYFUNCTION("""COMPUTED_VALUE"""),"Kururu") -> Kururu | K5: =IFERROR(__xludf.DUMMYFUNCTION("""COMPUTED_VALUE"""),26.0) -> 26 | L5: =IFERROR(__xludf.DUMMYFUNCTION("""COMPUTED_VALUE"""),4.0) -> 4 | M5: =IFERROR(__xludf.DUMMYFUNCTION("IMAGE(QUERY('Player Refs'!A:B,""SELECT B WHERE A = '""&J5&""'"",0))"),"") | O5: =IFERROR(__xludf.DUMMYFUNCTION("""COMPUTED_VALUE"""),"EIS") -> EIS | P5: =IFERROR(__xludf.DUMMYFUNCTION("""COMPUTED_VALUE"""),81.0) -> 81 | Q5: =IFERROR(__xludf.DUMMYFUNCTION("""COMPUTED_VALUE"""),7.0) -> 7 | R5: =IFERROR(__xludf.DUMMYFUNCTION("IMAGE(QUERY('Set Refs'!A:B,""SELECT B WHERE A = '""&O5&""'"",0))"),"")
A6: =IFERROR(__xludf.DUMMYFUNCTION("""COMPUTED_VALUE"""),"OVL") -> OVL | B6: =IFERROR(__xludf.DUMMYFUNCTION("""COMPUTED_VALUE"""),"8 Door") -> 8 Door | C6: =IFERROR(__xludf.DUMMYFUNCTION("""COMPUTED_VALUE"""),12.0) -> 12 | D6: =IFERROR(__xludf.DUMMYFUNCTION("""COMPUTED_VALUE"""),0.4676896608793401) -> 0.46768966 | E6: =IFERROR(__xludf.DUMMYFUNCTION("""COMPUTED_VALUE"""),0.75) -> 0.75 | F6: =IFERROR(__xludf.DUMMYFUNCTION("IF(A6="""","""",IMAGE(QUERY('Deck Info'!A:F,""SELECT D WHERE A = '""&A6&""' AND B = '""&B6&""'"")))"),"") | G6: =IFERROR(__xludf.DUMMYFUNCTION("IF(A6="""","""",IMAGE(QUERY('Deck Info'!A:F,""SELECT E WHERE A = '""&A6&""' AND B = '""&B6&""'"")))"),"") | H6: =IFERROR(__xludf.DUMMYFUNCTION("IF(A6="""","""",IMAGE(QUERY('Deck Info'!A:F,""SELECT F WHERE A = '""&A6&""' AND B = '""&B6&""'"")))"),"") | J6: =IFERROR(__xludf.DUMMYFUNCTION("""COMPUTED_VALUE"""),"Pinya") -> Pinya | K6: =IFERROR(__xludf.DUMMYFUNCTION("""COMPUTED_VALUE"""),26.0) -> 26 | L6: =IFERROR(__xludf.DUMMYFUNCTION("""COMPUTED_VALUE"""),2.0) -> 2 | M6: =IFERROR(__xludf.DUMMYFUNCTION("IMAGE(QUERY('Player Refs'!A:B,""SELECT B WHERE A = '""&J6&""'"",0))"),"") | O6: =IFERROR(__xludf.DUMMYFUNCTION("""COMPUTED_VALUE"""),"NIK") -> NIK | P6: =IFERROR(__xludf.DUMMYFUNCTION("""COMPUTED_VALUE"""),46.0) -> 46 | Q6: =IFERROR(__xludf.DUMMYFUNCTION("""COMPUTED_VALUE"""),6.0) -> 6 | R6: =IFERROR(__xludf.DUMMYFUNCTION("IMAGE(QUERY('Set Refs'!A:B,""SELECT B WHERE A = '""&O6&""'"",0))"),"")
A7: =IFERROR(__xludf.DUMMYFUNCTION("""COMPUTED_VALUE"""),"EIS") -> EIS | B7: =IFERROR(__xludf.DUMMYFUNCTION("""COMPUTED_VALUE"""),"8 Standby") -> 8 Standby | C7: =IFERROR(__xludf.DUMMYFUNCTION("""COMPUTED_VALUE"""),34.0) -> 34 | D7: =IFERROR(__xludf.DUMMYFUNCTION("""COMPUTED_VALUE"""),0.3945361778918369) -> 0.39453618 | E7: =IFERROR(__xludf.DUMMYFUNCTION("""COMPUTED_VALUE"""),0.5588235294117647) -> 0.55882353 | F7: =IFERROR(__xludf.DUMMYFUNCTION("IF(A7="""","""",IMAGE(QUERY('Deck Info'!A:F,""SELECT D WHERE A = '""&A7&""' AND B = '""&B7&""'"")))"),"") | G7: =IFERROR(__xludf.DUMMYFUNCTION("IF(A7="""","""",IMAGE(QUERY('Deck Info'!A:F,""SELECT E WHERE A = '""&A7&""' AND B = '""&B7&""'"")))"),"") | H7: =IFERROR(__xludf.DUMMYFUNCTION("IF(A7="""","""",IMAGE(QUERY('Deck Info'!A:F,""SELECT F WHERE A = '""&A7&""' AND B = '""&B7&""'"")))"),"") | J7: =IFERROR(__xludf.DUMMYFUNCTION("""COMPUTED_VALUE"""),"Will") -> Will | K7: =IFERROR(__xludf.DUMMYFUNCTION("""COMPUTED_VALUE"""),26.0) -> 26 | L7: =IFERROR(__xludf.DUMMYFUNCTION("""COMPUTED_VALUE"""),4.0) -> 4 | M7: =IFERROR(__xludf.DUMMYFUNCTION("IMAGE(QUERY('Player Refs'!A:B,""SELECT B WHERE A = '""&J7&""'"",0))"),"") | O7: =IFERROR(__xludf.DUMMYFUNCTION("""COMPUTED_VALUE"""),"OSK") -> OSK | P7: =IFERROR(__xludf.DUMMYFUNCTION("""COMPUTED_VALUE"""),31.0) -> 31 | Q7: =IFERROR(__xludf.DUMMYFUNCTION("""COMPUTED_VALUE"""),4.0) -> 4 | R7: =IFERROR(__xludf.DUMMYFUNCTION("IMAGE(QUERY('Set Refs'!A:B,""SELECT B WHERE A = '""&O7&""'"",0))"),"")
A8: =IFERROR(__xludf.DUMMYFUNCTION("""COMPUTED_VALUE"""),"CSM") -> CSM | B8: =IFERROR(__xludf.DUMMYFUNCTION("""COMPUTED_VALUE"""),"StockSoul Bar") -> StockSoul Bar | C8: =IFERROR(__xludf.DUMMYFUNCTION("""COMPUTED_VALUE"""),12.0) -> 12 | D8: =IFERROR(__xludf.DUMMYFUNCTION("""COMPUTED_VALUE"""),0.3906175873976139) -> 0.39061759 | E8: =IFERROR(__xludf.DUMMYFUNCTION("""COMPUTED_VALUE"""),0.6666666666666666) -> 0.66666667 | F8: =IFERROR(__xludf.DUMMYFUNCTION("IF(A8="""","""",IMAGE(QUERY('Deck Info'!A:F,""SELECT D WHERE A = '""&A8&""' AND B = '""&B8&""'"")))"),"") | G8: =IFERROR(__xludf.DUMMYFUNCTION("IF(A8="""","""",IMAGE(QUERY('Deck Info'!A:F,""SELECT E WHERE A = '""&A8&""' AND B = '""&B8&""'"")))"),"") | H8: =IFERROR(__xludf.DUMMYFUNCTION("IF(A8="""","""",IMAGE(QUERY('Deck Info'!A:F,""SELECT F WHERE A = '""&A8&""' AND B = '""&B8&""'"")))"),"") | J8: =IFERROR(__xludf.DUMMYFUNCTION("""COMPUTED_VALUE"""),"JustFluffy") -> JustFluffy | K8: =IFERROR(__xludf.DUMMYFUNCTION("""COMPUTED_VALUE"""),25.0) -> 25 | L8: =IFERROR(__xludf.DUMMYFUNCTION("""COMPUTED_VALUE"""),2.0) -> 2 | M8: =IFERROR(__xludf.DUMMYFUNCTION("IMAGE(QUERY('Player Refs'!A:B,""SELECT B WHERE A = '""&J8&""'"",0))"),"") | O8: =IFERROR(__xludf.DUMMYFUNCTION("""COMPUTED_VALUE"""),"MKI") -> MKI | P8: =IFERROR(__xludf.DUMMYFUNCTION("""COMPUTED_VALUE"""),22.0) -> 22 | Q8: =IFERROR(__xludf.DUMMYFUNCTION("""COMPUTED_VALUE"""),2.0) -> 2 | R8: =IFERROR(__xludf.DUMMYFUNCTION("IMAGE(QUERY('Set Refs'!A:B,""SELECT B WHERE A = '""&O8&""'"",0))"),"")
A9: =IFERROR(__xludf.DUMMYFUNCTION("""COMPUTED_VALUE"""),"NIK") -> NIK | B9: =IFERROR(__xludf.DUMMYFUNCTION("""COMPUTED_VALUE"""),"Door Standby") -> Door Standby | C9: =IFERROR(__xludf.DUMMYFUNCTION("""COMPUTED_VALUE"""),42.0) -> 42 | D9: =IFERROR(__xludf.DUMMYFUNCTION("""COMPUTED_VALUE"""),0.3552574591652803) -> 0.35525746 | E9: =IFERROR(__xludf.DUMMYFUNCTION("""COMPUTED_VALUE"""),0.5) -> 0.5 | F9: =IFERROR(__xludf.DUMMYFUNCTION("IF(A9="""","""",IMAGE(QUERY('Deck Info'!A:F,""SELECT D WHERE A = '""&A9&""' AND B = '""&B9&""'"")))"),"") | G9: =IFERROR(__xludf.DUMMYFUNCTION("IF(A9="""","""",IMAGE(QUERY('Deck Info'!A:F,""SELECT E WHERE A = '""&A9&""' AND B = '""&B9&""'"")))"),"") | H9: =IFERROR(__xludf.DUMMYFUNCTION("IF(A9="""","""",IMAGE(QUERY('Deck Info'!A:F,""SELECT F WHERE A = '""&A9&""' AND B = '""&B9&""'"")))"),"") | J9: =IFERROR(__xludf.DUMMYFUNCTION("""COMPUTED_VALUE"""),"Agus") -> Agus | K9: =IFERROR(__xludf.DUMMYFUNCTION("""COMPUTED_VALUE"""),22.0) -> 22 | L9: =IFERROR(__xludf.DUMMYFUNCTION("""COMPUTED_VALUE"""),2.0) -> 2 | M9: =IFERROR(__xludf.DUMMYFUNCTION("IMAGE(QUERY('Player Refs'!A:B,""SELECT B WHERE A = '""&J9&""'"",0))"),"") | O9: =IFERROR(__xludf.DUMMYFUNCTION("""COMPUTED_VALUE"""),"CSM") -> CSM | P9: =IFERROR(__xludf.DUMMYFUNCTION("""COMPUTED_VALUE"""),16.0) -> 16 | Q9: =IFERROR(__xludf.DUMMYFUNCTION("""COMPUTED_VALUE"""),2.0) -> 2 | R9: =IFERROR(__xludf.DUMMYFUNCTION("IMAGE(QUERY('Set Refs'!A:B,""SELECT B WHERE A = '""&O9&""'"",0))"),"")
A10: =IFERROR(__xludf.DUMMYFUNCTION("""COMPUTED_VALUE"""),"DAL") -> DAL | B10: =IFERROR(__xludf.DUMMYFUNCTION("""COMPUTED_VALUE"""),"8 Standby") -> 8 Standby | C10: =IFERROR(__xludf.DUMMYFUNCTION("""COMPUTED_VALUE"""),13.0) -> 13 | D10: =IFERROR(__xludf.DUMMYFUNCTION("""COMPUTED_VALUE"""),0.3552248097226855) -> 0.35522481 | E10: =IFERROR(__xludf.DUMMYFUNCTION("""COMPUTED_VALUE"""),0.6153846153846154) -> 0.61538462 | F10: =IFERROR(__xludf.DUMMYFUNCTION("IF(A10="""","""",IMAGE(QUERY('Deck Info'!A:F,""SELECT D WHERE A = '""&A10&""' AND B = '""&B10&""'"")))"),"") | G10: =IFERROR(__xludf.DUMMYFUNCTION("IF(A10="""","""",IMAGE(QUERY('Deck Info'!A:F,""SELECT E WHERE A = '""&A10&""' AND B = '""&B10&""'"")))"),"") | H10: =IFERROR(__xludf.DUMMYFUNCTION("IF(A10="""","""",IMAGE(QUERY('Deck Info'!A:F,""SELECT F WHERE A = '""&A10&""' AND B = '""&B10&""'"")))"),"") | J10: =IFERROR(__xludf.DUMMYFUNCTION("""COMPUTED_VALUE"""),"Mualco") -> Mualco | K10: =IFERROR(__xludf.DUMMYFUNCTION("""COMPUTED_VALUE"""),22.0) -> 22 | L10: =IFERROR(__xludf.DUMMYFUNCTION("""COMPUTED_VALUE"""),4.0) -> 4 | M10: =IFERROR(__xludf.DUMMYFUNCTION("IMAGE(QUERY('Player Refs'!A:B,""SELECT B WHERE A = '""&J10&""'"",0))"),"") | O10: =IFERROR(__xludf.DUMMYFUNCTION("""COMPUTED_VALUE"""),"AZL") -> AZL | P10: =IFERROR(__xludf.DUMMYFUNCTION("""COMPUTED_VALUE"""),14.0) -> 14 | Q10: =IFERROR(__xludf.DUMMYFUNCTION("""COMPUTED_VALUE"""),1.0) -> 1 | R10: =IFERROR(__xludf.DUMMYFUNCTION("IMAGE(QUERY('Set Refs'!A:B,""SELECT B WHERE A = '""&O10&""'"",0))"),"")
A11: =IFERROR(__xludf.DUMMYFUNCTION("""COMPUTED_VALUE"""),"DDD") -> DDD | B11: =IFERROR(__xludf.DUMMYFUNCTION("""COMPUTED_VALUE"""),"8 Choice") -> 8 Choice | C11: =IFERROR(__xludf.DUMMYFUNCTION("""COMPUTED_VALUE"""),10.0) -> 10 | D11: =IFERROR(__xludf.DUMMYFUNCTION("""COMPUTED_VALUE"""),0.3126695474501863) -> 0.31266955 | E11: =IFERROR(__xludf.DUMMYFUNCTION("""COMPUTED_VALUE"""),0.6) -> 0.6 | F11: =IFERROR(__xludf.DUMMYFUNCTION("IF(A11="""","""",IMAGE(QUERY('Deck Info'!A:F,""SELECT D WHERE A = '""&A11&""' AND B = '""&B11&""'"")))"),"") | G11: =IFERROR(__xludf.DUMMYFUNCTION("IF(A11="""","""",IMAGE(QUERY('Deck Info'!A:F,""SELECT E WHERE A = '""&A11&""' AND B = '""&B11&""'"")))"),"") | H11: =IFERROR(__xludf.DUMMYFUNCTION("IF(A11="""","""",IMAGE(QUERY('Deck Info'!A:F,""SELECT F WHERE A = '""&A11&""' AND B = '""&B11&""'"")))"),"") | J11: =IFERROR(__xludf.DUMMYFUNCTION("""COMPUTED_VALUE"""),"Nomar") -> Nomar | K11: =IFERROR(__xludf.DUMMYFUNCTION("""COMPUTED_VALUE"""),22.0) -> 22 | L11: =IFERROR(__xludf.DUMMYFUNCTION("""COMPUTED_VALUE"""),4.0) -> 4 | M11: =IFERROR(__xludf.DUMMYFUNCTION("IMAGE(QUERY('Player Refs'!A:B,""SELECT B WHERE A = '""&J11&""'"",0))"),"") | O11: =IFERROR(__xludf.DUMMYFUNCTION("""COMPUTED_VALUE"""),"DDD") -> DDD | P11: =IFERROR(__xludf.DUMMYFUNCTION("""COMPUTED_VALUE"""),14.0) -> 14 | Q11: =IFERROR(__xludf.DUMMYFUNCTION("""COMPUTED_VALUE"""),2.0) -> 2 | R11: =IFERROR(__xludf.DUMMYFUNCTION("IMAGE(QUERY('Set Refs'!A:B,""SELECT B WHERE A = '""&O11&""'"",0))"),"")
A12: =IFERROR(__xludf.DUMMYFUNCTION("""COMPUTED_VALUE"""),"MKI") -> MKI | B12: =IFERROR(__xludf.DUMMYFUNCTION("""COMPUTED_VALUE"""),"8 Door") -> 8 Door | C12: =IFERROR(__xludf.DUMMYFUNCTION("""COMPUTED_VALUE"""),18.0) -> 18 | D12: =IFERROR(__xludf.DUMMYFUNCTION("""COMPUTED_VALUE"""),0.24559231101389123) -> 0.24559231 | E12: =IFERROR(__xludf.DUMMYFUNCTION("""COMPUTED_VALUE"""),0.4444444444444444) -> 0.44444444 | F12: =IFERROR(__xludf.DUMMYFUNCTION("IF(A12="""","""",IMAGE(QUERY('Deck Info'!A:F,""SELECT D WHERE A = '""&A12&""' AND B = '""&B12&""'"")))"),"") | G12: =IFERROR(__xludf.DUMMYFUNCTION("IF(A12="""","""",IMAGE(QUERY('Deck Info'!A:F,""SELECT E WHERE A = '""&A12&""' AND B = '""&B12&""'"")))"),"") | H12: =IFERROR(__xludf.DUMMYFUNCTION("IF(A12="""","""",IMAGE(QUERY('Deck Info'!A:F,""SELECT F WHERE A = '""&A12&""' AND B = '""&B12&""'"")))"),"") | J12: =IFERROR(__xludf.DUMMYFUNCTION("""COMPUTED_VALUE"""),"Rehmius") -> Rehmius | K12: =IFERROR(__xludf.DUMMYFUNCTION("""COMPUTED_VALUE"""),22.0) -> 22 | L12: =IFERROR(__xludf.DUMMYFUNCTION("""COMPUTED_VALUE"""),3.0) -> 3 | M12: =IFERROR(__xludf.DUMMYFUNCTION("IMAGE(QUERY('Player Refs'!A:B,""SELECT B WHERE A = '""&J12&""'"",0))"),"") | O12: =IFERROR(__xludf.DUMMYFUNCTION("""COMPUTED_VALUE"""),"Fxx") -> Fxx | P12: =IFERROR(__xludf.DUMMYFUNCTION("""COMPUTED_VALUE"""),14.0) -> 14 | Q12: =IFERROR(__xludf.DUMMYFUNCTION("""COMPUTED_VALUE"""),3.0) -> 3 | R12: =IFERROR(__xludf.DUMMYFUNCTION("IMAGE(QUERY('Set Refs'!A:B,""SELECT B WHERE A = '""&O12&""'"",0))"),"")
A13: =IFERROR(__xludf.DUMMYFUNCTION("""COMPUTED_VALUE"""),"GCR") -> GCR | B13: =IFERROR(__xludf.DUMMYFUNCTION("""COMPUTED_VALUE"""),"8 Door") -> 8 Door | C13: =IFERROR(__xludf.DUMMYFUNCTION("""COMPUTED_VALUE"""),13.0) -> 13 | D13: =IFERROR(__xludf.DUMMYFUNCTION("""COMPUTED_VALUE"""),0.23205754301488138) -> 0.23205754 | E13: =IFERROR(__xludf.DUMMYFUNCTION("""COMPUTED_VALUE"""),0.46153846153846156) -> 0.46153846 | F13: =IFERROR(__xludf.DUMMYFUNCTION("IF(A13="""","""",IMAGE(QUERY('Deck Info'!A:F,""SELECT D WHERE A = '""&A13&""' AND B = '""&B13&""'"")))"),"") | G13: =IFERROR(__xludf.DUMMYFUNCTION("IF(A13="""","""",IMAGE(QUERY('Deck Info'!A:F,""SELECT E WHERE A = '""&A13&""' AND B = '""&B13&""'"")))"),"") | H13: =IFERROR(__xludf.DUMMYFUNCTION("IF(A13="""","""",IMAGE(QUERY('Deck Info'!A:F,""SELECT F WHERE A = '""&A13&""' AND B = '""&B13&""'"")))"),"") | J13: =IFERROR(__xludf.DUMMYFUNCTION("""COMPUTED_VALUE"""),"Seyer") -> Seyer | K13: =IFERROR(__xludf.DUMMYFUNCTION("""COMPUTED_VALUE"""),21.0) -> 21 | L13: =IFERROR(__xludf.DUMMYFUNCTION("""COMPUTED_VALUE"""),4.0) -> 4 | M13: =IFERROR(__xludf.DUMMYFUNCTION("IMAGE(QUERY('Player Refs'!A:B,""SELECT B WHERE A = '""&J13&""'"",0))"),"") | O13: =IFERROR(__xludf.DUMMYFUNCTION("""COMPUTED_VALUE"""),"DAL") -> DAL | P13: =IFERROR(__xludf.DUMMYFUNCTION("""COMPUTED_VALUE"""),13.0) -> 13 | Q13: =IFERROR(__xludf.DUMMYFUNCTION("""COMPUTED_VALUE"""),1.0) -> 1 | R13: =IFERROR(__xludf.DUMMYFUNCTION("IMAGE(QUERY('Set Refs'!A:B,""SELECT B WHERE A = '""&O13&""'"",0))"),"")
F14: =IFERROR(__xludf.DUMMYFUNCTION("IF(A14="""","""",IMAGE(QUERY('Deck Info'!A:F,""SELECT D WHERE A = '""&A14&""' AND B = '""&B14&""'"")))"),"") | G14: =IFERROR(__xludf.DUMMYFUNCTION("IF(A14="""","""",IMAGE(QUERY('Deck Info'!A:F,""SELECT E WHERE A = '""&A14&""' AND B = '""&B14&""'"")))"),"") | H14: =IFERROR(__xludf.DUMMYFUNCTION("IF(A14="""","""",IMAGE(QUERY('Deck Info'!A:F,""SELECT F WHERE A = '""&A14&""' AND B = '""&B14&""'"")))"),"") | J14: =IFERROR(__xludf.DUMMYFUNCTION("""COMPUTED_VALUE"""),"Angladita") -> Angladita | K14: =IFERROR(__xludf.DUMMYFUNCTION("""COMPUTED_VALUE"""),18.0) -> 18 | L14: =IFERROR(__xludf.DUMMYFUNCTION("""COMPUTED_VALUE"""),3.0) -> 3 | M14: =IFERROR(__xludf.DUMMYFUNCTION("IMAGE(QUERY('Player Refs'!A:B,""SELECT B WHERE A = '""&J14&""'"",0))"),"") | R14: =IFERROR(__xludf.DUMMYFUNCTION("IMAGE(QUERY('Set Refs'!A:B,""SELECT B WHERE A = '""&O14&""'"",0))"),"")
F15: =IFERROR(__xludf.DUMMYFUNCTION("IF(A15="""","""",IMAGE(QUERY('Deck Info'!A:F,""SELECT D WHERE A = '""&A15&""' AND B = '""&B15&""'"")))"),"") | G15: =IFERROR(__xludf.DUMMYFUNCTION("IF(A15="""","""",IMAGE(QUERY('Deck Info'!A:F,""SELECT E WHERE A = '""&A15&""' AND B = '""&B15&""'"")))"),"") | H15: =IFERROR(__xludf.DUMMYFUNCTION("IF(A15="""","""",IMAGE(QUERY('Deck Info'!A:F,""SELECT F WHERE A = '""&A15&""' AND B = '""&B15&""'"")))"),"") | J15: =IFERROR(__xludf.DUMMYFUNCTION("""COMPUTED_VALUE"""),"YoniTheRobot") -> YoniTheRobot | K15: =IFERROR(__xludf.DUMMYFUNCTION("""COMPUTED_VALUE"""),18.0) -> 18 | L15: =IFERROR(__xludf.DUMMYFUNCTION("""COMPUTED_VALUE"""),3.0) -> 3 | M15: =IFERROR(__xludf.DUMMYFUNCTION("IMAGE(QUERY('Player Refs'!A:B,""SELECT B WHERE A = '""&J15&""'"",0))"),"") | R15: =IFERROR(__xludf.DUMMYFUNCTION("IMAGE(QUERY('Set Refs'!A:B,""SELECT B WHERE A = '""&O15&""'"",0))"),"")
F16: =IFERROR(__xludf.DUMMYFUNCTION("IF(A16="""","""",IMAGE(QUERY('Deck Info'!A:F,""SELECT D WHERE A = '""&A16&""' AND B = '""&B16&""'"")))"),"") | G16: =IFERROR(__xludf.DUMMYFUNCTION("IF(A16="""","""",IMAGE(QUERY('Deck Info'!A:F,""SELECT E WHERE A = '""&A16&""' AND B = '""&B16&""'"")))"),"") | H16: =IFERROR(__xludf.DUMMYFUNCTION("IF(A16="""","""",IMAGE(QUERY('Deck Info'!A:F,""SELECT F WHERE A = '""&A16&""' AND B = '""&B16&""'"")))"),"") | J16: =IFERROR(__xludf.DUMMYFUNCTION("""COMPUTED_VALUE"""),"AC5") -> AC5 | K16: =IFERROR(__xludf.DUMMYFUNCTION("""COMPUTED_VALUE"""),16.0) -> 16 | L16: =IFERROR(__xludf.DUMMYFUNCTION("""COMPUTED_VALUE"""),1.0) -> 1 | M16: =IFERROR(__xludf.DUMMYFUNCTION("IMAGE(QUERY('Player Refs'!A:B,""SELECT B WHERE A = '""&J16&""'"",0))"),"") | R16: =IFERROR(__xludf.DUMMYFUNCTION("IMAGE(QUERY('Set Refs'!A:B,""SELECT B WHERE A = '""&O16&""'"",0))"),"")
F17: =IFERROR(__xludf.DUMMYFUNCTION("IF(A17="""","""",IMAGE(QUERY('Deck Info'!A:F,""SELECT D WHERE A = '""&A17&""' AND B = '""&B17&""'"")))"),"") | G17: =IFERROR(__xludf.DUMMYFUNCTION("IF(A17="""","""",IMAGE(QUERY('Deck Info'!A:F,""SELECT E WHERE A = '""&A17&""' AND B = '""&B17&""'"")))"),"") | H17: =IFERROR(__xludf.DUMMYFUNCTION("IF(A17="""","""",IMAGE(QUERY('Deck Info'!A:F,""SELECT F WHERE A = '""&A17&""' AND B = '""&B17&""'"")))"),"") | J17: =IFERROR(__xludf.DUMMYFUNCTION("""COMPUTED_VALUE"""),"Calvo Tieso") -> Calvo Tieso | K17: =IFERROR(__xludf.DUMMYFUNCTION("""COMPUTED_VALUE"""),14.0) -> 14 | L17: =IFERROR(__xludf.DUMMYFUNCTION("""COMPUTED_VALUE"""),1.0) -> 1 | M17: =IFERROR(__xludf.DUMMYFUNCTION("IMAGE(QUERY('Player Refs'!A:B,""SELECT B WHERE A = '""&J17&""'"",0))"),"") | R17: =IFERROR(__xludf.DUMMYFUNCTION("IMAGE(QUERY('Set Refs'!A:B,""SELECT B WHERE A = '""&O17&""'"",0))"),"")
F18: =IFERROR(__xludf.DUMMYFUNCTION("IF(A18="""","""",IMAGE(QUERY('Deck Info'!A:F,""SELECT D WHERE A = '""&A18&""' AND B = '""&B18&""'"")))"),"") | G18: =IFERROR(__xludf.DUMMYFUNCTION("IF(A18="""","""",IMAGE(QUERY('Deck Info'!A:F,""SELECT E WHERE A = '""&A18&""' AND B = '""&B18&""'"")))"),"") | H18: =IFERROR(__xludf.DUMMYFUNCTION("IF(A18="""","""",IMAGE(QUERY('Deck Info'!A:F,""SELECT F WHERE A = '""&A18&""' AND B = '""&B18&""'"")))"),"") | J18: =IFERROR(__xludf.DUMMYFUNCTION("""COMPUTED_VALUE"""),"Zeno") -> Zeno | K18: =IFERROR(__xludf.DUMMYFUNCTION("""COMPUTED_VALUE"""),14.0) -> 14 | L18: =IFERROR(__xludf.DUMMYFUNCTION("""COMPUTED_VALUE"""),2.0) -> 2 | M18: =IFERROR(__xludf.DUMMYFUNCTION("IMAGE(QUERY('Player Refs'!A:B,""SELECT B WHERE A = '""&J18&""'"",0))"),"") | R18: =IFERROR(__xludf.DUMMYFUNCTION("IMAGE(QUERY('Set Refs'!A:B,""SELECT B WHERE A = '""&O18&""'"",0))"),"")
F19: =IFERROR(__xludf.DUMMYFUNCTION("IF(A19="""","""",IMAGE(QUERY('Deck Info'!A:F,""SELECT D WHERE A = '""&A19&""' AND B = '""&B19&""'"")))"),"") | G19: =IFERROR(__xludf.DUMMYFUNCTION("IF(A19="""","""",IMAGE(QUERY('Deck Info'!A:F,""SELECT E WHERE A = '""&A19&""' AND B = '""&B19&""'"")))"),"") | H19: =IFERROR(__xludf.DUMMYFUNCTION("IF(A19="""","""",IMAGE(QUERY('Deck Info'!A:F,""SELECT F WHERE A = '""&A19&""' AND B = '""&B19&""'"")))"),"") | J19: =IFERROR(__xludf.DUMMYFUNCTION("""COMPUTED_VALUE"""),"Ruto") -> Ruto | K19: =IFERROR(__xludf.DUMMYFUNCTION("""COMPUTED_VALUE"""),13.0) -> 13 | L19: =IFERROR(__xludf.DUMMYFUNCTION("""COMPUTED_VALUE"""),3.0) -> 3 | M19: =IFERROR(__xludf.DUMMYFUNCTION("IMAGE(QUERY('Player Refs'!A:B,""SELECT B WHERE A = '""&J19&""'"",0))"),"") | R19: =IFERROR(__xludf.DUMMYFUNCTION("IMAGE(QUERY('Set Refs'!A:B,""SELECT B WHERE A = '""&O19&""'"",0))"),"")
F20: =IFERROR(__xludf.DUMMYFUNCTION("IF(A20="""","""",IMAGE(QUERY('Deck Info'!A:F,""SELECT D WHERE A = '""&A20&""' AND B = '""&B20&""'"")))"),"") | G20: =IFERROR(__xludf.DUMMYFUNCTION("IF(A20="""","""",IMAGE(QUERY('Deck Info'!A:F,""SELECT E WHERE A = '""&A20&""' AND B = '""&B20&""'"")))"),"") | H20: =IFERROR(__xludf.DUMMYFUNCTION("IF(A20="""","""",IMAGE(QUERY('Deck Info'!A:F,""SELECT F WHERE A = '""&A20&""' AND B = '""&B20&""'"")))"),"") | J20: =IFERROR(__xludf.DUMMYFUNCTION("""COMPUTED_VALUE"""),"STARK") -> STARK | K20: =IFERROR(__xludf.DUMMYFUNCTION("""COMPUTED_VALUE"""),13.0) -> 13 | L20: =IFERROR(__xludf.DUMMYFUNCTION("""COMPUTED_VALUE"""),3.0) -> 3 | M20: =IFERROR(__xludf.DUMMYFUNCTION("IMAGE(QUERY('Player Refs'!A:B,""SELECT B WHERE A = '""&J20&""'"",0))"),"") | R20: =IFERROR(__xludf.DUMMYFUNCTION("IMAGE(QUERY('Set Refs'!A:B,""SELECT B WHERE A = '""&O20&""'"",0))"),"")
J21: =IFERROR(__xludf.DUMMYFUNCTION("""COMPUTED_VALUE"""),"Sp3ctrum") -> Sp3ctrum | K21: =IFERROR(__xludf.DUMMYFUNCTION("""COMPUTED_VALUE"""),13.0) -> 13 | L21: =IFERROR(__xludf.DUMMYFUNCTION("""COMPUTED_VALUE"""),2.0) -> 2 | M21: =IFERROR(__xludf.DUMMYFUNCTION("IMAGE(QUERY('Player Refs'!A:B,""SELECT B WHERE A = '""&J21&""'"",0))"),"") | R21: =IFERROR(__xludf.DUMMYFUNCTION("IMAGE(QUERY('Set Refs'!A:B,""SELECT B WHERE A = '""&O21&""'"",0))"),"")
J22: =IFERROR(__xludf.DUMMYFUNCTION("""COMPUTED_VALUE"""),"SoulQualia") -> SoulQualia | K22: =IFERROR(__xludf.DUMMYFUNCTION("""COMPUTED_VALUE"""),12.0) -> 12 | L22: =IFERROR(__xludf.DUMMYFUNCTION("""COMPUTED_VALUE"""),1.0) -> 1 | M22: =IFERROR(__xludf.DUMMYFUNCTION("IMAGE(QUERY('Player Refs'!A:B,""SELECT B WHERE A = '""&J22&""'"",0))"),"") | R22: =IFERROR(__xludf.DUMMYFUNCTION("IMAGE(QUERY('Set Refs'!A:B,""SELECT B WHERE A = '""&O22&""'"",0))"),"")
J23: =IFERROR(__xludf.DUMMYFUNCTION("""COMPUTED_VALUE"""),"Charlie") -> Charlie | K23: =IFERROR(__xludf.DUMMYFUNCTION("""COMPUTED_VALUE"""),10.0) -> 10 | L23: =IFERROR(__xludf.DUMMYFUNCTION("""COMPUTED_VALUE"""),1.0) -> 1 | M23: =IFERROR(__xludf.DUMMYFUNCTION("IMAGE(QUERY('Player Refs'!A:B,""SELECT B WHERE A = '""&J23&""'"",0))"),"") | R23: =IFERROR(__xludf.DUMMYFUNCTION("IMAGE(QUERY('Set Refs'!A:B,""SELECT B WHERE A = '""&O23&""'"",0))"),"")
R24: =IFERROR(__xludf.DUMMYFUNCTION("IMAGE(QUERY('Set Refs'!A:B,""SELECT B WHERE A = '""&O24&""'"",0))"),"")
R25: =IFERROR(__xludf.DUMMYFUNCTION("IMAGE(QUERY('Set Refs'!A:B,""SELECT B WHERE A = '""&O25&""'"",0))"),"")
R26: =IFERROR(__xludf.DUMMYFUNCTION("IMAGE(QUERY('Set Refs'!A:B,""SELECT B WHERE A = '""&O26&""'"",0))"),"")
R27: =IFERROR(__xludf.DUMMYFUNCTION("IMAGE(QUERY('Set Refs'!A:B,""SELECT B WHERE A = '""&O27&""'"",0))"),"")

Sheet Ranking mensual
A1: Deck con mayor Win% del mes | K1: Mayor asistencia mensual | P1: Representacion de sets
A3: Set | B3: Deck | C3: Partidas Jugadas | D3: Win % | E3: Carta 1 | F3: Carta 2 | G3: Carta 3 | H3: Description | K3: Jugador | L3: Partidas jugadas | N3: Signature | P3: Set | Q3: Partidas | R3: Jugadores | S3: Imagen
A4: =IFERROR(__xludf.DUMMYFUNCTION("QUERY( Set_Stats!R4:W1000, ""SELECT Col1,Col2,Col6,Col5 WHERE Col6 >= 5 AND Col1 <> '?' AND Col2 <> '?' ORDER BY Col5 DESC"", 0 )"),"#N/A") -> #N/A | E4: =IFERROR(__xludf.DUMMYFUNCTION("IF(A4="""","""",IMAGE(QUERY('Deck Info'!A:F,""SELECT D WHERE A = '""&A4&""' AND B = '""&B4&""'"")))"),"#N/A") -> #N/A | F4: =IFERROR(__xludf.DUMMYFUNCTION("IF(A4="""","""",IMAGE(QUERY('Deck Info'!A:F,""SELECT E WHERE A = '""&A4&""' AND B = '""&B4&""'"")))"),"#N/A") -> #N/A | G4: =IFERROR(__xludf.DUMMYFUNCTION("IF(A4="""","""",IMAGE(QUERY('Deck Info'!A:F,""SELECT F WHERE A = '""&A4&""' AND B = '""&B4&""'"")))"),"#N/A") -> #N/A | K4: =IFERROR(__xludf.DUMMYFUNCTION("QUERY( 'Raw Data'!AB:AC, ""SELECT Col1,Col2 ORDER BY Col2 DESC LIMIT 20"", 0 )"),"Jugador") -> Jugador | L4: =IFERROR(__xludf.DUMMYFUNCTION("""COMPUTED_VALUE"""),"Partidas Jugadas") -> Partidas Jugadas | N4: =IFERROR(__xludf.DUMMYFUNCTION("IMAGE(QUERY('Player Refs'!A:B,""SELECT B WHERE A = '""&K4&""'"",0))"),"#N/A") -> #N/A | P4: =IFERROR(__xludf.DUMMYFUNCTION("QUERY( Set_Stats!N4:P1000, ""SELECT N,O,P WHERE N IS NOT NULL ORDER BY O DESC LIMIT 10"", 0 )"),"#N/A") -> #N/A | R4: =IFERROR(__xludf.DUMMYFUNCTION("""COMPUTED_VALUE"""),1.0) -> 1 | S4: =IFERROR(__xludf.DUMMYFUNCTION("IMAGE(QUERY('Set Refs'!A:B,""SELECT B WHERE A = '""&P4&""'"",0))"),"#N/A") -> #N/A
E5: =IFERROR(__xludf.DUMMYFUNCTION("IF(A5="""","""",IMAGE(QUERY('Deck Info'!A:F,""SELECT D WHERE A = '""&A5&""' AND B = '""&B5&""'"")))"),"") | F5: =IFERROR(__xludf.DUMMYFUNCTION("IF(A5="""","""",IMAGE(QUERY('Deck Info'!A:F,""SELECT E WHERE A = '""&A5&""' AND B = '""&B5&""'"")))"),"") | G5: =IFERROR(__xludf.DUMMYFUNCTION("IF(A5="""","""",IMAGE(QUERY('Deck Info'!A:F,""SELECT F WHERE A = '""&A5&""' AND B = '""&B5&""'"")))"),"") | N5: =IFERROR(__xludf.DUMMYFUNCTION("IMAGE(QUERY('Player Refs'!A:B,""SELECT B WHERE A = '""&K5&""'"",0))"),"") | S5: =IFERROR(__xludf.DUMMYFUNCTION("IMAGE(QUERY('Set Refs'!A:B,""SELECT B WHERE A = '""&P5&""'"",0))"),"")
E6: =IFERROR(__xludf.DUMMYFUNCTION("IF(A6="""","""",IMAGE(QUERY('Deck Info'!A:F,""SELECT D WHERE A = '""&A6&""' AND B = '""&B6&""'"")))"),"") | F6: =IFERROR(__xludf.DUMMYFUNCTION("IF(A6="""","""",IMAGE(QUERY('Deck Info'!A:F,""SELECT E WHERE A = '""&A6&""' AND B = '""&B6&""'"")))"),"") | G6: =IFERROR(__xludf.DUMMYFUNCTION("IF(A6="""","""",IMAGE(QUERY('Deck Info'!A:F,""SELECT F WHERE A = '""&A6&""' AND B = '""&B6&""'"")))"),"") | N6: =IFERROR(__xludf.DUMMYFUNCTION("IMAGE(QUERY('Player Refs'!A:B,""SELECT B WHERE A = '""&K6&""'"",0))"),"") | S6: =IFERROR(__xludf.DUMMYFUNCTION("IMAGE(QUERY('Set Refs'!A:B,""SELECT B WHERE A = '""&P6&""'"",0))"),"")
E7: =IFERROR(__xludf.DUMMYFUNCTION("IF(A7="""","""",IMAGE(QUERY('Deck Info'!A:F,""SELECT D WHERE A = '""&A7&""' AND B = '""&B7&""'"")))"),"") | F7: =IFERROR(__xludf.DUMMYFUNCTION("IF(A7="""","""",IMAGE(QUERY('Deck Info'!A:F,""SELECT E WHERE A = '""&A7&""' AND B = '""&B7&""'"")))"),"") | G7: =IFERROR(__xludf.DUMMYFUNCTION("IF(A7="""","""",IMAGE(QUERY('Deck Info'!A:F,""SELECT F WHERE A = '""&A7&""' AND B = '""&B7&""'"")))"),"") | N7: =IFERROR(__xludf.DUMMYFUNCTION("IMAGE(QUERY('Player Refs'!A:B,""SELECT B WHERE A = '""&K7&""'"",0))"),"") | S7: =IFERROR(__xludf.DUMMYFUNCTION("IMAGE(QUERY('Set Refs'!A:B,""SELECT B WHERE A = '""&P7&""'"",0))"),"")
E8: =IFERROR(__xludf.DUMMYFUNCTION("IF(A8="""","""",IMAGE(QUERY('Deck Info'!A:F,""SELECT D WHERE A = '""&A8&""' AND B = '""&B8&""'"")))"),"") | F8: =IFERROR(__xludf.DUMMYFUNCTION("IF(A8="""","""",IMAGE(QUERY('Deck Info'!A:F,""SELECT E WHERE A = '""&A8&""' AND B = '""&B8&""'"")))"),"") | G8: =IFERROR(__xludf.DUMMYFUNCTION("IF(A8="""","""",IMAGE(QUERY('Deck Info'!A:F,""SELECT F WHERE A = '""&A8&""' AND B = '""&B8&""'"")))"),"") | N8: =IFERROR(__xludf.DUMMYFUNCTION("IMAGE(QUERY('Player Refs'!A:B,""SELECT B WHERE A = '""&K8&""'"",0))"),"") | S8: =IFERROR(__xludf.DUMMYFUNCTION("IMAGE(QUERY('Set Refs'!A:B,""SELECT B WHERE A = '""&P8&""'"",0))"),"")
E9: =IFERROR(__xludf.DUMMYFUNCTION("IF(A9="""","""",IMAGE(QUERY('Deck Info'!A:F,""SELECT D WHERE A = '""&A9&""' AND B = '""&B9&""'"")))"),"") | F9: =IFERROR(__xludf.DUMMYFUNCTION("IF(A9="""","""",IMAGE(QUERY('Deck Info'!A:F,""SELECT E WHERE A = '""&A9&""' AND B = '""&B9&""'"")))"),"") | G9: =IFERROR(__xludf.DUMMYFUNCTION("IF(A9="""","""",IMAGE(QUERY('Deck Info'!A:F,""SELECT F WHERE A = '""&A9&""' AND B = '""&B9&""'"")))"),"") | N9: =IFERROR(__xludf.DUMMYFUNCTION("IMAGE(QUERY('Player Refs'!A:B,""SELECT B WHERE A = '""&K9&""'"",0))"),"") | S9: =IFERROR(__xludf.DUMMYFUNCTION("IMAGE(QUERY('Set Refs'!A:B,""SELECT B WHERE A = '""&P9&""'"",0))"),"")
E10: =IFERROR(__xludf.DUMMYFUNCTION("IF(A10="""","""",IMAGE(QUERY('Deck Info'!A:F,""SELECT D WHERE A = '""&A10&""' AND B = '""&B10&""'"")))"),"") | F10: =IFERROR(__xludf.DUMMYFUNCTION("IF(A10="""","""",IMAGE(QUERY('Deck Info'!A:F,""SELECT E WHERE A = '""&A10&""' AND B = '""&B10&""'"")))"),"") | G10: =IFERROR(__xludf.DUMMYFUNCTION("IF(A10="""","""",IMAGE(QUERY('Deck Info'!A:F,""SELECT F WHERE A = '""&A10&""' AND B = '""&B10&""'"")))"),"") | N10: =IFERROR(__xludf.DUMMYFUNCTION("IMAGE(QUERY('Player Refs'!A:B,""SELECT B WHERE A = '""&K10&""'"",0))"),"") | S10: =IFERROR(__xludf.DUMMYFUNCTION("IMAGE(QUERY('Set Refs'!A:B,""SELECT B WHERE A = '""&P10&""'"",0))"),"")
E11: =IFERROR(__xludf.DUMMYFUNCTION("IF(A11="""","""",IMAGE(QUERY('Deck Info'!A:F,""SELECT D WHERE A = '""&A11&""' AND B = '""&B11&""'"")))"),"") | F11: =IFERROR(__xludf.DUMMYFUNCTION("IF(A11="""","""",IMAGE(QUERY('Deck Info'!A:F,""SELECT E WHERE A = '""&A11&""' AND B = '""&B11&""'"")))"),"") | G11: =IFERROR(__xludf.DUMMYFUNCTION("IF(A11="""","""",IMAGE(QUERY('Deck Info'!A:F,""SELECT F WHERE A = '""&A11&""' AND B = '""&B11&""'"")))"),"") | N11: =IFERROR(__xludf.DUMMYFUNCTION("IMAGE(QUERY('Player Refs'!A:B,""SELECT B WHERE A = '""&K11&""'"",0))"),"") | S11: =IFERROR(__xludf.DUMMYFUNCTION("IMAGE(QUERY('Set Refs'!A:B,""SELECT B WHERE A = '""&P11&""'"",0))"),"")
E12: =IFERROR(__xludf.DUMMYFUNCTION("IF(A12="""","""",IMAGE(QUERY('Deck Info'!A:F,""SELECT D WHERE A = '""&A12&""' AND B = '""&B12&""'"")))"),"") | F12: =IFERROR(__xludf.DUMMYFUNCTION("IF(A12="""","""",IMAGE(QUERY('Deck Info'!A:F,""SELECT E WHERE A = '""&A12&""' AND B = '""&B12&""'"")))"),"") | G12: =IFERROR(__xludf.DUMMYFUNCTION("IF(A12="""","""",IMAGE(QUERY('Deck Info'!A:F,""SELECT F WHERE A = '""&A12&""' AND B = '""&B12&""'"")))"),"") | N12: =IFERROR(__xludf.DUMMYFUNCTION("IMAGE(QUERY('Player Refs'!A:B,""SELECT B WHERE A = '""&K12&""'"",0))"),"") | S12: =IFERROR(__xludf.DUMMYFUNCTION("IMAGE(QUERY('Set Refs'!A:B,""SELECT B WHERE A = '""&P12&""'"",0))"),"")
E13: =IFERROR(__xludf.DUMMYFUNCTION("IF(A13="""","""",IMAGE(QUERY('Deck Info'!A:F,""SELECT D WHERE A = '""&A13&""' AND B = '""&B13&""'"")))"),"") | F13: =IFERROR(__xludf.DUMMYFUNCTION("IF(A13="""","""",IMAGE(QUERY('Deck Info'!A:F,""SELECT E WHERE A = '""&A13&""' AND B = '""&B13&""'"")))"),"") | G13: =IFERROR(__xludf.DUMMYFUNCTION("IF(A13="""","""",IMAGE(QUERY('Deck Info'!A:F,""SELECT F WHERE A = '""&A13&""' AND B = '""&B13&""'"")))"),"") | N13: =IFERROR(__xludf.DUMMYFUNCTION("IMAGE(QUERY('Player Refs'!A:B,""SELECT B WHERE A = '""&K13&""'"",0))"),"") | S13: =IFERROR(__xludf.DUMMYFUNCTION("IMAGE(QUERY('Set Refs'!A:B,""SELECT B WHERE A = '""&P13&""'"",0))"),"")
E14: =IFERROR(__xludf.DUMMYFUNCTION("IF(A14="""","""",IMAGE(QUERY('Deck Info'!A:F,""SELECT D WHERE A = '""&A14&""' AND B = '""&B14&""'"")))"),"") | F14: =IFERROR(__xludf.DUMMYFUNCTION("IF(A14="""","""",IMAGE(QUERY('Deck Info'!A:F,""SELECT E WHERE A = '""&A14&""' AND B = '""&B14&""'"")))"),"") | G14: =IFERROR(__xludf.DUMMYFUNCTION("IF(A14="""","""",IMAGE(QUERY('Deck Info'!A:F,""SELECT F WHERE A = '""&A14&""' AND B = '""&B14&""'"")))"),"") | N14: =IFERROR(__xludf.DUMMYFUNCTION("IMAGE(QUERY('Player Refs'!A:B,""SELECT B WHERE A = '""&K14&""'"",0))"),"") | S14: =IFERROR(__xludf.DUMMYFUNCTION("IMAGE(QUERY('Set Refs'!A:B,""SELECT B WHERE A = '""&P14&""'"",0))"),"")
E15: =IFERROR(__xludf.DUMMYFUNCTION("IF(A15="""","""",IMAGE(QUERY('Deck Info'!A:F,""SELECT D WHERE A = '""&A15&""' AND B = '""&B15&""'"")))"),"") | F15: =IFERROR(__xludf.DUMMYFUNCTION("IF(A15="""","""",IMAGE(QUERY('Deck Info'!A:F,""SELECT E WHERE A = '""&A15&""' AND B = '""&B15&""'"")))"),"") | G15: =IFERROR(__xludf.DUMMYFUNCTION("IF(A15="""","""",IMAGE(QUERY('Deck Info'!A:F,""SELECT F WHERE A = '""&A15&""' AND B = '""&B15&""'"")))"),"") | N15: =IFERROR(__xludf.DUMMYFUNCTION("IMAGE(QUERY('Player Refs'!A:B,""SELECT B WHERE A = '""&K15&""'"",0))"),"") | S15: =IFERROR(__xludf.DUMMYFUNCTION("IMAGE(QUERY('Set Refs'!A:B,""SELECT B WHERE A = '""&P15&""'"",0))"),"")
E16: =IFERROR(__xludf.DUMMYFUNCTION("IF(A16="""","""",IMAGE(QUERY('Deck Info'!A:F,""SELECT D WHERE A = '""&A16&""' AND B = '""&B16&""'"")))"),"") | F16: =IFERROR(__xludf.DUMMYFUNCTION("IF(A16="""","""",IMAGE(QUERY('Deck Info'!A:F,""SELECT E WHERE A = '""&A16&""' AND B = '""&B16&""'"")))"),"") | G16: =IFERROR(__xludf.DUMMYFUNCTION("IF(A16="""","""",IMAGE(QUERY('Deck Info'!A:F,""SELECT F WHERE A = '""&A16&""' AND B = '""&B16&""'"")))"),"") | N16: =IFERROR(__xludf.DUMMYFUNCTION("IMAGE(QUERY('Player Refs'!A:B,""SELECT B WHERE A = '""&K16&""'"",0))"),"") | S16: =IFERROR(__xludf.DUMMYFUNCTION("IMAGE(QUERY('Set Refs'!A:B,""SELECT B WHERE A = '""&P16&""'"",0))"),"")
E17: =IFERROR(__xludf.DUMMYFUNCTION("IF(A17="""","""",IMAGE(QUERY('Deck Info'!A:F,""SELECT D WHERE A = '""&A17&""' AND B = '""&B17&""'"")))"),"") | F17: =IFERROR(__xludf.DUMMYFUNCTION("IF(A17="""","""",IMAGE(QUERY('Deck Info'!A:F,""SELECT E WHERE A = '""&A17&""' AND B = '""&B17&""'"")))"),"") | G17: =IFERROR(__xludf.DUMMYFUNCTION("IF(A17="""","""",IMAGE(QUERY('Deck Info'!A:F,""SELECT F WHERE A = '""&A17&""' AND B = '""&B17&""'"")))"),"") | N17: =IFERROR(__xludf.DUMMYFUNCTION("IMAGE(QUERY('Player Refs'!A:B,""SELECT B WHERE A = '""&K17&""'"",0))"),"") | S17: =IFERROR(__xludf.DUMMYFUNCTION("IMAGE(QUERY('Set Refs'!A:B,""SELECT B WHERE A = '""&P17&""'"",0))"),"")
E18: =IFERROR(__xludf.DUMMYFUNCTION("IF(A18="""","""",IMAGE(QUERY('Deck Info'!A:F,""SELECT D WHERE A = '""&A18&""' AND B = '""&B18&""'"")))"),"") | F18: =IFERROR(__xludf.DUMMYFUNCTION("IF(A18="""","""",IMAGE(QUERY('Deck Info'!A:F,""SELECT E WHERE A = '""&A18&""' AND B = '""&B18&""'"")))"),"") | G18: =IFERROR(__xludf.DUMMYFUNCTION("IF(A18="""","""",IMAGE(QUERY('Deck Info'!A:F,""SELECT F WHERE A = '""&A18&""' AND B = '""&B18&""'"")))"),"") | N18: =IFERROR(__xludf.DUMMYFUNCTION("IMAGE(QUERY('Player Refs'!A:B,""SELECT B WHERE A = '""&K18&""'"",0))"),"") | S18: =IFERROR(__xludf.DUMMYFUNCTION("IMAGE(QUERY('Set Refs'!A:B,""SELECT B WHERE A = '""&P18&""'"",0))"),"")
E19: =IFERROR(__xludf.DUMMYFUNCTION("IF(A19="""","""",IMAGE(QUERY('Deck Info'!A:F,""SELECT D WHERE A = '""&A19&""' AND B = '""&B19&""'"")))"),"") | F19: =IFERROR(__xludf.DUMMYFUNCTION("IF(A19="""","""",IMAGE(QUERY('Deck Info'!A:F,""SELECT E WHERE A = '""&A19&""' AND B = '""&B19&""'"")))"),"") | G19: =IFERROR(__xludf.DUMMYFUNCTION("IF(A19="""","""",IMAGE(QUERY('Deck Info'!A:F,""SELECT F WHERE A = '""&A19&""' AND B = '""&B19&""'"")))"),"") | N19: =IFERROR(__xludf.DUMMYFUNCTION("IMAGE(QUERY('Player Refs'!A:B,""SELECT B WHERE A = '""&K19&""'"",0))"),"") | S19: =IFERROR(__xludf.DUMMYFUNCTION("IMAGE(QUERY('Set Refs'!A:B,""SELECT B WHERE A = '""&P19&""'"",0))"),"")
E20: =IFERROR(__xludf.DUMMYFUNCTION("IF(A20="""","""",IMAGE(QUERY('Deck Info'!A:F,""SELECT D WHERE A = '""&A20&""' AND B = '""&B20&""'"")))"),"") | F20: =IFERROR(__xludf.DUMMYFUNCTION("IF(A20="""","""",IMAGE(QUERY('Deck Info'!A:F,""SELECT E WHERE A = '""&A20&""' AND B = '""&B20&""'"")))"),"") | G20: =IFERROR(__xludf.DUMMYFUNCTION("IF(A20="""","""",IMAGE(QUERY('Deck Info'!A:F,""SELECT F WHERE A = '""&A20&""' AND B = '""&B20&""'"")))"),"") | N20: =IFERROR(__xludf.DUMMYFUNCTION("IMAGE(QUERY('Player Refs'!A:B,""SELECT B WHERE A = '""&K20&""'"",0))"),"") | S20: =IFERROR(__xludf.DUMMYFUNCTION("IMAGE(QUERY('Set Refs'!A:B,""SELECT B WHERE A = '""&P20&""'"",0))"),"")
N21: =IFERROR(__xludf.DUMMYFUNCTION("IMAGE(QUERY('Player Refs'!A:B,""SELECT B WHERE A = '""&K21&""'"",0))"),"") | S21: =IFERROR(__xludf.DUMMYFUNCTION("IMAGE(QUERY('Set Refs'!A:B,""SELECT B WHERE A = '""&P21&""'"",0))"),"")
N22: =IFERROR(__xludf.DUMMYFUNCTION("IMAGE(QUERY('Player Refs'!A:B,""SELECT B WHERE A = '""&K22&""'"",0))"),"") | S22: =IFERROR(__xludf.DUMMYFUNCTION("IMAGE(QUERY('Set Refs'!A:B,""SELECT B WHERE A = '""&P22&""'"",0))"),"")
N23: =IFERROR(__xludf.DUMMYFUNCTION("IMAGE(QUERY('Player Refs'!A:B,""SELECT B WHERE A = '""&K23&""'"",0))"),"") | S23: =IFERROR(__xludf.DUMMYFUNCTION("IMAGE(QUERY('Set Refs'!A:B,""SELECT B WHERE A = '""&P23&""'"",0))"),"")

Sheet Torneos Recientes
A1: EMPIRE GAMES (Local) | I1: EMPIRE GAMES (WSEC) | Q1: EMPIRE GAMES (Local) | Y1: EMPIRE GAMES (WSEC) | AG1: EMPIRE GAMES
A2: 46179 | I2: 46186 | Q2: 46193 | Y2: 46200
A3: =IFERROR(__xludf.DUMMYFUNCTION("QUERY( 'Raw Data'!B:G, ""SELECT Col2,Col3,Col4,Col5,Col6 WHERE Col1 = date '""&TEXT(A2,""yyyy-MM-dd"")&""' ORDER BY Col5 DESC LABEL Col2 'Jugador', Col3 'Set', Col4 'Deck', Col5 'Wins', Col6 'Losses'"", 1 )"),"Jugador") -> Jugador | B3: =IFERROR(__xludf.DUMMYFUNCTION("""COMPUTED_VALUE"""),"Set") -> Set | C3: =IFERROR(__xludf.DUMMYFUNCTION("""COMPUTED_VALUE"""),"Deck") -> Deck | D3: =IFERROR(__xludf.DUMMYFUNCTION("""COMPUTED_VALUE"""),"Wins") -> Wins | E3: =IFERROR(__xludf.DUMMYFUNCTION("""COMPUTED_VALUE"""),"Losses") -> Losses | F3: Img | G3: Img | H3: Img | I3: =IFERROR(__xludf.DUMMYFUNCTION("QUERY( 'Raw Data'!B:G, ""SELECT Col2,Col3,Col4,Col5,Col6 WHERE Col1 = date '""&TEXT(I2,""yyyy-MM-dd"")&""' ORDER BY Col5 DESC LABEL Col2 'Jugador', Col3 'Set', Col4 'Arquetipo', Col5 'Wins', Col6 'Losses'"", 1 )"),"Jugador") -> Jugador | J3: =IFERROR(__xludf.DUMMYFUNCTION("""COMPUTED_VALUE"""),"Set") -> Set | K3: =IFERROR(__xludf.DUMMYFUNCTION("""COMPUTED_VALUE"""),"Arquetipo") -> Arquetipo | L3: =IFERROR(__xludf.DUMMYFUNCTION("""COMPUTED_VALUE"""),"Wins") -> Wins | M3: =IFERROR(__xludf.DUMMYFUNCTION("""COMPUTED_VALUE"""),"Losses") -> Losses | N3: Img | O3: Img | P3: Img | Q3: =IFERROR(__xludf.DUMMYFUNCTION("QUERY( 'Raw Data'!B:G, ""SELECT Col2,Col3,Col4,Col5,Col6 WHERE Col1 = date '""&TEXT(Q2,""yyyy-MM-dd"")&""' ORDER BY Col5 DESC LABEL Col2 'Jugador', Col3 'Set', Col4 'Arquetipo', Col5 'Wins', Col6 'Losses'"", 1 )"),"Jugador") -> Jugador | R3: =IFERROR(__xludf.DUMMYFUNCTION("""COMPUTED_VALUE"""),"Set") -> Set | S3: =IFERROR(__xludf.DUMMYFUNCTION("""COMPUTED_VALUE"""),"Arquetipo") -> Arquetipo | T3: =IFERROR(__xludf.DUMMYFUNCTION("""COMPUTED_VALUE"""),"Wins") -> Wins | U3: =IFERROR(__xludf.DUMMYFUNCTION("""COMPUTED_VALUE"""),"Losses") -> Losses | V3: Img | W3: Img | X3: Img | Y3: =IFERROR(__xludf.DUMMYFUNCTION("QUERY( 'Raw Data'!B:G, ""SELECT Col2,Col3,Col4,Col5,Col6 WHERE Col1 = date '""&TEXT(Y2,""yyyy-MM-dd"")&""' ORDER BY Col5 DESC LABEL Col2 'Jugador', Col3 'Set', Col4 'Arquetipo', Col5 'Wins', Col6 'Losses'"", 1 )"),"Jugador") -> Jugador | Z3: =IFERROR(__xludf.DUMMYFUNCTION("""COMPUTED_VALUE"""),"Set") -> Set | AA3: =IFERROR(__xludf.DUMMYFUNCTION("""COMPUTED_VALUE"""),"Arquetipo") -> Arquetipo | AB3: =IFERROR(__xludf.DUMMYFUNCTION("""COMPUTED_VALUE"""),"Wins") -> Wins | AC3: =IFERROR(__xludf.DUMMYFUNCTION("""COMPUTED_VALUE"""),"Losses") -> Losses | AD3: Img | AE3: Img | AF3: Img | AG3: =IFERROR(__xludf.DUMMYFUNCTION("QUERY( 'Raw Data'!B:G, ""SELECT Col2,Col3,Col4,Col5,Col6 WHERE Col1 = date '""&TEXT(AG2,""yyyy-MM-dd"")&""' ORDER BY Col5 DESC LABEL Col2 'Jugador', Col3 'Set', Col4 'Arquetipo', Col5 'Wins', Col6 'Losses'"", 1 )"),"Jugador") -> Jugador | AH3: =IFERROR(__xludf.DUMMYFUNCTION("""COMPUTED_VALUE"""),"Set") -> Set | AI3: =IFERROR(__xludf.DUMMYFUNCTION("""COMPUTED_VALUE"""),"Arquetipo") -> Arquetipo | AJ3: =IFERROR(__xludf.DUMMYFUNCTION("""COMPUTED_VALUE"""),"Wins") -> Wins | AK3: =IFERROR(__xludf.DUMMYFUNCTION("""COMPUTED_VALUE"""),"Losses") -> Losses | AL3: Img | AM3: Img | AN3: Img
A4: =IFERROR(__xludf.DUMMYFUNCTION("""COMPUTED_VALUE"""),"Pinya") -> Pinya | B4: =IFERROR(__xludf.DUMMYFUNCTION("""COMPUTED_VALUE"""),"EIS") -> EIS | C4: =IFERROR(__xludf.DUMMYFUNCTION("""COMPUTED_VALUE"""),"8 Door TD") -> 8 Door TD | D4: =IFERROR(__xludf.DUMMYFUNCTION("""COMPUTED_VALUE"""),4.0) -> 4 | E4: =IFERROR(__xludf.DUMMYFUNCTION("""COMPUTED_VALUE"""),0.0) -> 0 | F4: =IFERROR(__xludf.DUMMYFUNCTION("IF(A4="""","""",IMAGE(QUERY('Deck Info'!A:F,""SELECT D WHERE A = '""&B4&""' AND B = '""&C4&""'"")))"),"") | G4: =IFERROR(__xludf.DUMMYFUNCTION("IF(A4="""","""",IMAGE(QUERY('Deck Info'!A:F,""SELECT E WHERE A = '""&B4&""' AND B = '""&C4&""'"")))"),"") | H4: =IFERROR(__xludf.DUMMYFUNCTION("IF(A4="""","""",IMAGE(QUERY('Deck Info'!A:F,""SELECT F WHERE A = '""&B4&""' AND B = '""&C4&""'"")))"),"") | I4: =IFERROR(__xludf.DUMMYFUNCTION("""COMPUTED_VALUE"""),"Velz") -> Velz | J4: =IFERROR(__xludf.DUMMYFUNCTION("""COMPUTED_VALUE"""),"OVL") -> OVL | K4: =IFERROR(__xludf.DUMMYFUNCTION("""COMPUTED_VALUE"""),"8 Door") -> 8 Door | L4: =IFERROR(__xludf.DUMMYFUNCTION("""COMPUTED_VALUE"""),4.0) -> 4 | M4: =IFERROR(__xludf.DUMMYFUNCTION("""COMPUTED_VALUE"""),0.0) -> 0 | N4: =IFERROR(__xludf.DUMMYFUNCTION("IF(I4="""","""",IMAGE(QUERY('Deck Info'!A:F,""SELECT D WHERE A = '""&J4&""' AND B = '""&K4&""'"")))"),"") | O4: =IFERROR(__xludf.DUMMYFUNCTION("IF(I4="""","""",IMAGE(QUERY('Deck Info'!A:F,""SELECT E WHERE A = '""&J4&""' AND B = '""&K4&""'"")))"),"") | P4: =IFERROR(__xludf.DUMMYFUNCTION("IF(I4="""","""",IMAGE(QUERY('Deck Info'!A:F,""SELECT F WHERE A = '""&J4&""' AND B = '""&K4&""'"")))"),"") | V4: =IFERROR(__xludf.DUMMYFUNCTION("IF(Q4="""","""",IMAGE(QUERY('Deck Info'!A:F,""SELECT D WHERE A = '""&R4&""' AND B = '""&S4&""'"")))"),"") | W4: =IFERROR(__xludf.DUMMYFUNCTION("IF(Q4="""","""",IMAGE(QUERY('Deck Info'!A:F,""SELECT E WHERE A = '""&R4&""' AND B = '""&S4&""'"")))"),"") | X4: =IFERROR(__xludf.DUMMYFUNCTION("IF(Q4="""","""",IMAGE(QUERY('Deck Info'!A:F,""SELECT F WHERE A = '""&R4&""' AND B = '""&S4&""'"")))"),"") | AD4: =IFERROR(__xludf.DUMMYFUNCTION("IF(Y4="""","""",IMAGE(QUERY('Deck Info'!A:F,""SELECT D WHERE A = '""&Z4&""' AND B = '""&AA4&""'"")))"),"") | AE4: =IFERROR(__xludf.DUMMYFUNCTION("IF(Y4="""","""",IMAGE(QUERY('Deck Info'!A:F,""SELECT E WHERE A = '""&Z4&""' AND B = '""&AA4&""'"")))"),"") | AF4: =IFERROR(__xludf.DUMMYFUNCTION("IF(Y4="""","""",IMAGE(QUERY('Deck Info'!A:F,""SELECT F WHERE A = '""&Z4&""' AND B = '""&AA4&""'"")))"),"") | AL4: =IFERROR(__xludf.DUMMYFUNCTION("IF(AG4="""","""",IMAGE(QUERY('Deck Info'!A:F,""SELECT D WHERE A = '""&AH4&""' AND B = '""&AI4&""'"")))"),"") | AM4: =IFERROR(__xludf.DUMMYFUNCTION("IF(AG4="""","""",IMAGE(QUERY('Deck Info'!A:F,""SELECT E WHERE A = '""&AH4&""' AND B = '""&AI4&""'"")))"),"") | AN4: =IFERROR(__xludf.DUMMYFUNCTION("IF(AG4="""","""",IMAGE(QUERY('Deck Info'!A:F,""SELECT F WHERE A = '""&AH4&""' AND B = '""&AI4&""'"")))"),"")
A5: =IFERROR(__xludf.DUMMYFUNCTION("""COMPUTED_VALUE"""),"Seyer") -> Seyer | B5: =IFERROR(__xludf.DUMMYFUNCTION("""COMPUTED_VALUE"""),"CSM") -> CSM | C5: =IFERROR(__xludf.DUMMYFUNCTION("""COMPUTED_VALUE"""),"StockSoul Standby") -> StockSoul Standby | D5: =IFERROR(__xludf.DUMMYFUNCTION("""COMPUTED_VALUE"""),3.0) -> 3 | E5: =IFERROR(__xludf.DUMMYFUNCTION("""COMPUTED_VALUE"""),1.0) -> 1 | F5: =IFERROR(__xludf.DUMMYFUNCTION("IF(A5="""","""",IMAGE(QUERY('Deck Info'!A:F,""SELECT D WHERE A = '""&B5&""' AND B = '""&C5&""'"")))"),"") | G5: =IFERROR(__xludf.DUMMYFUNCTION("IF(A5="""","""",IMAGE(QUERY('Deck Info'!A:F,""SELECT E WHERE A = '""&B5&""' AND B = '""&C5&""'"")))"),"") | H5: =IFERROR(__xludf.DUMMYFUNCTION("IF(A5="""","""",IMAGE(QUERY('Deck Info'!A:F,""SELECT F WHERE A = '""&B5&""' AND B = '""&C5&""'"")))"),"") | I5: =IFERROR(__xludf.DUMMYFUNCTION("""COMPUTED_VALUE"""),"Seyer") -> Seyer | J5: =IFERROR(__xludf.DUMMYFUNCTION("""COMPUTED_VALUE"""),"CSM") -> CSM | K5: =IFERROR(__xludf.DUMMYFUNCTION("""COMPUTED_VALUE"""),"StockSoul Bar") -> StockSoul Bar | L5: =IFERROR(__xludf.DUMMYFUNCTION("""COMPUTED_VALUE"""),3.0) -> 3 | M5: =IFERROR(__xludf.DUMMYFUNCTION("""COMPUTED_VALUE"""),1.0) -> 1 | N5: =IFERROR(__xludf.DUMMYFUNCTION("IF(I5="""","""",IMAGE(QUERY('Deck Info'!A:F,""SELECT D WHERE A = '""&J5&""' AND B = '""&K5&""'"")))"),"") | O5: =IFERROR(__xludf.DUMMYFUNCTION("IF(I5="""","""",IMAGE(QUERY('Deck Info'!A:F,""SELECT E WHERE A = '""&J5&""' AND B = '""&K5&""'"")))"),"") | P5: =IFERROR(__xludf.DUMMYFUNCTION("IF(I5="""","""",IMAGE(QUERY('Deck Info'!A:F,""SELECT F WHERE A = '""&J5&""' AND B = '""&K5&""'"")))"),"") | V5: =IFERROR(__xludf.DUMMYFUNCTION("IF(Q5="""","""",IMAGE(QUERY('Deck Info'!A:F,""SELECT D WHERE A = '""&R5&""' AND B = '""&S5&""'"")))"),"") | W5: =IFERROR(__xludf.DUMMYFUNCTION("IF(Q5="""","""",IMAGE(QUERY('Deck Info'!A:F,""SELECT E WHERE A = '""&R5&""' AND B = '""&S5&""'"")))"),"") | X5: =IFERROR(__xludf.DUMMYFUNCTION("IF(Q5="""","""",IMAGE(QUERY('Deck Info'!A:F,""SELECT F WHERE A = '""&R5&""' AND B = '""&S5&""'"")))"),"") | AD5: =IFERROR(__xludf.DUMMYFUNCTION("IF(Y5="""","""",IMAGE(QUERY('Deck Info'!A:F,""SELECT D WHERE A = '""&Z5&""' AND B = '""&AA5&""'"")))"),"") | AE5: =IFERROR(__xludf.DUMMYFUNCTION("IF(Y5="""","""",IMAGE(QUERY('Deck Info'!A:F,""SELECT E WHERE A = '""&Z5&""' AND B = '""&AA5&""'"")))"),"") | AF5: =IFERROR(__xludf.DUMMYFUNCTION("IF(Y5="""","""",IMAGE(QUERY('Deck Info'!A:F,""SELECT F WHERE A = '""&Z5&""' AND B = '""&AA5&""'"")))"),"") | AL5: =IFERROR(__xludf.DUMMYFUNCTION("IF(AG5="""","""",IMAGE(QUERY('Deck Info'!A:F,""SELECT D WHERE A = '""&AH5&""' AND B = '""&AI5&""'"")))"),"") | AM5: =IFERROR(__xludf.DUMMYFUNCTION("IF(AG5="""","""",IMAGE(QUERY('Deck Info'!A:F,""SELECT E WHERE A = '""&AH5&""' AND B = '""&AI5&""'"")))"),"") | AN5: =IFERROR(__xludf.DUMMYFUNCTION("IF(AG5="""","""",IMAGE(QUERY('Deck Info'!A:F,""SELECT F WHERE A = '""&AH5&""' AND B = '""&AI5&""'"")))"),"")
A6: =IFERROR(__xludf.DUMMYFUNCTION("""COMPUTED_VALUE"""),"Angladita") -> Angladita | B6: =IFERROR(__xludf.DUMMYFUNCTION("""COMPUTED_VALUE"""),"OVL") -> OVL | C6: =IFERROR(__xludf.DUMMYFUNCTION("""COMPUTED_VALUE"""),"8 Door") -> 8 Door | D6: =IFERROR(__xludf.DUMMYFUNCTION("""COMPUTED_VALUE"""),3.0) -> 3 | E6: =IFERROR(__xludf.DUMMYFUNCTION("""COMPUTED_VALUE"""),1.0) -> 1 | F6: =IFERROR(__xludf.DUMMYFUNCTION("IF(A6="""","""",IMAGE(QUERY('Deck Info'!A:F,""SELECT D WHERE A = '""&B6&""' AND B = '""&C6&""'"")))"),"") | G6: =IFERROR(__xludf.DUMMYFUNCTION("IF(A6="""","""",IMAGE(QUERY('Deck Info'!A:F,""SELECT E WHERE A = '""&B6&""' AND B = '""&C6&""'"")))"),"") | H6: =IFERROR(__xludf.DUMMYFUNCTION("IF(A6="""","""",IMAGE(QUERY('Deck Info'!A:F,""SELECT F WHERE A = '""&B6&""' AND B = '""&C6&""'"")))"),"") | I6: =IFERROR(__xludf.DUMMYFUNCTION("""COMPUTED_VALUE"""),"Sp3ctrum") -> Sp3ctrum | J6: =IFERROR(__xludf.DUMMYFUNCTION("""COMPUTED_VALUE"""),"BD") -> BD | K6: =IFERROR(__xludf.DUMMYFUNCTION("""COMPUTED_VALUE"""),"Bar Door") -> Bar Door | L6: =IFERROR(__xludf.DUMMYFUNCTION("""COMPUTED_VALUE"""),3.0) -> 3 | M6: =IFERROR(__xludf.DUMMYFUNCTION("""COMPUTED_VALUE"""),1.0) -> 1 | N6: =IFERROR(__xludf.DUMMYFUNCTION("IF(I6="""","""",IMAGE(QUERY('Deck Info'!A:F,""SELECT D WHERE A = '""&J6&""' AND B = '""&K6&""'"")))"),"") | O6: =IFERROR(__xludf.DUMMYFUNCTION("IF(I6="""","""",IMAGE(QUERY('Deck Info'!A:F,""SELECT E WHERE A = '""&J6&""' AND B = '""&K6&""'"")))"),"") | P6: =IFERROR(__xludf.DUMMYFUNCTION("IF(I6="""","""",IMAGE(QUERY('Deck Info'!A:F,""SELECT F WHERE A = '""&J6&""' AND B = '""&K6&""'"")))"),"") | V6: =IFERROR(__xludf.DUMMYFUNCTION("IF(Q6="""","""",IMAGE(QUERY('Deck Info'!A:F,""SELECT D WHERE A = '""&R6&""' AND B = '""&S6&""'"")))"),"") | W6: =IFERROR(__xludf.DUMMYFUNCTION("IF(Q6="""","""",IMAGE(QUERY('Deck Info'!A:F,""SELECT E WHERE A = '""&R6&""' AND B = '""&S6&""'"")))"),"") | X6: =IFERROR(__xludf.DUMMYFUNCTION("IF(Q6="""","""",IMAGE(QUERY('Deck Info'!A:F,""SELECT F WHERE A = '""&R6&""' AND B = '""&S6&""'"")))"),"") | AD6: =IFERROR(__xludf.DUMMYFUNCTION("IF(Y6="""","""",IMAGE(QUERY('Deck Info'!A:F,""SELECT D WHERE A = '""&Z6&""' AND B = '""&AA6&""'"")))"),"") | AE6: =IFERROR(__xludf.DUMMYFUNCTION("IF(Y6="""","""",IMAGE(QUERY('Deck Info'!A:F,""SELECT E WHERE A = '""&Z6&""' AND B = '""&AA6&""'"")))"),"") | AF6: =IFERROR(__xludf.DUMMYFUNCTION("IF(Y6="""","""",IMAGE(QUERY('Deck Info'!A:F,""SELECT F WHERE A = '""&Z6&""' AND B = '""&AA6&""'"")))"),"") | AL6: =IFERROR(__xludf.DUMMYFUNCTION("IF(AG6="""","""",IMAGE(QUERY('Deck Info'!A:F,""SELECT D WHERE A = '""&AH6&""' AND B = '""&AI6&""'"")))"),"") | AM6: =IFERROR(__xludf.DUMMYFUNCTION("IF(AG6="""","""",IMAGE(QUERY('Deck Info'!A:F,""SELECT E WHERE A = '""&AH6&""' AND B = '""&AI6&""'"")))"),"") | AN6: =IFERROR(__xludf.DUMMYFUNCTION("IF(AG6="""","""",IMAGE(QUERY('Deck Info'!A:F,""SELECT F WHERE A = '""&AH6&""' AND B = '""&AI6&""'"")))"),"")
A7: =IFERROR(__xludf.DUMMYFUNCTION("""COMPUTED_VALUE"""),"Kartoffel") -> Kartoffel | B7: =IFERROR(__xludf.DUMMYFUNCTION("""COMPUTED_VALUE"""),"CSM") -> CSM | C7: =IFERROR(__xludf.DUMMYFUNCTION("""COMPUTED_VALUE"""),"StockSoul Bar") -> StockSoul Bar | D7: =IFERROR(__xludf.DUMMYFUNCTION("""COMPUTED_VALUE"""),2.0) -> 2 | E7: =IFERROR(__xludf.DUMMYFUNCTION("""COMPUTED_VALUE"""),2.0) -> 2 | F7: =IFERROR(__xludf.DUMMYFUNCTION("IF(A7="""","""",IMAGE(QUERY('Deck Info'!A:F,""SELECT D WHERE A = '""&B7&""' AND B = '""&C7&""'"")))"),"") | G7: =IFERROR(__xludf.DUMMYFUNCTION("IF(A7="""","""",IMAGE(QUERY('Deck Info'!A:F,""SELECT E WHERE A = '""&B7&""' AND B = '""&C7&""'"")))"),"") | H7: =IFERROR(__xludf.DUMMYFUNCTION("IF(A7="""","""",IMAGE(QUERY('Deck Info'!A:F,""SELECT F WHERE A = '""&B7&""' AND B = '""&C7&""'"")))"),"") | I7: =IFERROR(__xludf.DUMMYFUNCTION("""COMPUTED_VALUE"""),"JustFluffy") -> JustFluffy | J7: =IFERROR(__xludf.DUMMYFUNCTION("""COMPUTED_VALUE"""),"EIS") -> EIS | K7: =IFERROR(__xludf.DUMMYFUNCTION("""COMPUTED_VALUE"""),"5 Door 3 Pants Sortie") -> 5 Door 3 Pants Sortie | L7: =IFERROR(__xludf.DUMMYFUNCTION("""COMPUTED_VALUE"""),3.0) -> 3 | M7: =IFERROR(__xludf.DUMMYFUNCTION("""COMPUTED_VALUE"""),1.0) -> 1 | N7: =IFERROR(__xludf.DUMMYFUNCTION("IF(I7="""","""",IMAGE(QUERY('Deck Info'!A:F,""SELECT D WHERE A = '""&J7&""' AND B = '""&K7&""'"")))"),"#N/A") -> #N/A | O7: =IFERROR(__xludf.DUMMYFUNCTION("IF(I7="""","""",IMAGE(QUERY('Deck Info'!A:F,""SELECT E WHERE A = '""&J7&""' AND B = '""&K7&""'"")))"),"#N/A") -> #N/A | P7: =IFERROR(__xludf.DUMMYFUNCTION("IF(I7="""","""",IMAGE(QUERY('Deck Info'!A:F,""SELECT F WHERE A = '""&J7&""' AND B = '""&K7&""'"")))"),"#N/A") -> #N/A | V7: =IFERROR(__xludf.DUMMYFUNCTION("IF(Q7="""","""",IMAGE(QUERY('Deck Info'!A:F,""SELECT D WHERE A = '""&R7&""' AND B = '""&S7&""'"")))"),"") | W7: =IFERROR(__xludf.DUMMYFUNCTION("IF(Q7="""","""",IMAGE(QUERY('Deck Info'!A:F,""SELECT E WHERE A = '""&R7&""' AND B = '""&S7&""'"")))"),"") | X7: =IFERROR(__xludf.DUMMYFUNCTION("IF(Q7="""","""",IMAGE(QUERY('Deck Info'!A:F,""SELECT F WHERE A = '""&R7&""' AND B = '""&S7&""'"")))"),"") | AD7: =IFERROR(__xludf.DUMMYFUNCTION("IF(Y7="""","""",IMAGE(QUERY('Deck Info'!A:F,""SELECT D WHERE A = '""&Z7&""' AND B = '""&AA7&""'"")))"),"") | AE7: =IFERROR(__xludf.DUMMYFUNCTION("IF(Y7="""","""",IMAGE(QUERY('Deck Info'!A:F,""SELECT E WHERE A = '""&Z7&""' AND B = '""&AA7&""'"")))"),"") | AF7: =IFERROR(__xludf.DUMMYFUNCTION("IF(Y7="""","""",IMAGE(QUERY('Deck Info'!A:F,""SELECT F WHERE A = '""&Z7&""' AND B = '""&AA7&""'"")))"),"") | AL7: =IFERROR(__xludf.DUMMYFUNCTION("IF(AG7="""","""",IMAGE(QUERY('Deck Info'!A:F,""SELECT D WHERE A = '""&AH7&""' AND B = '""&AI7&""'"")))"),"") | AM7: =IFERROR(__xludf.DUMMYFUNCTION("IF(AG7="""","""",IMAGE(QUERY('Deck Info'!A:F,""SELECT E WHERE A = '""&AH7&""' AND B = '""&AI7&""'"")))"),"") | AN7: =IFERROR(__xludf.DUMMYFUNCTION("IF(AG7="""","""",IMAGE(QUERY('Deck Info'!A:F,""SELECT F WHERE A = '""&AH7&""' AND B = '""&AI7&""'"")))"),"")
A8: =IFERROR(__xludf.DUMMYFUNCTION("""COMPUTED_VALUE"""),"Mualco") -> Mualco | B8: =IFERROR(__xludf.DUMMYFUNCTION("""COMPUTED_VALUE"""),"Fxx") -> Fxx | C8: =IFERROR(__xludf.DUMMYFUNCTION("""COMPUTED_VALUE"""),"8 Standby") -> 8 Standby | D8: =IFERROR(__xludf.DUMMYFUNCTION("""COMPUTED_VALUE"""),2.0) -> 2 | E8: =IFERROR(__xludf.DUMMYFUNCTION("""COMPUTED_VALUE"""),2.0) -> 2 | F8: =IFERROR(__xludf.DUMMYFUNCTION("IF(A8="""","""",IMAGE(QUERY('Deck Info'!A:F,""SELECT D WHERE A = '""&B8&""' AND B = '""&C8&""'"")))"),"") | G8: =IFERROR(__xludf.DUMMYFUNCTION("IF(A8="""","""",IMAGE(QUERY('Deck Info'!A:F,""SELECT E WHERE A = '""&B8&""' AND B = '""&C8&""'"")))"),"") | H8: =IFERROR(__xludf.DUMMYFUNCTION("IF(A8="""","""",IMAGE(QUERY('Deck Info'!A:F,""SELECT F WHERE A = '""&B8&""' AND B = '""&C8&""'"")))"),"") | I8: =IFERROR(__xludf.DUMMYFUNCTION("""COMPUTED_VALUE"""),"Pinya") -> Pinya | J8: =IFERROR(__xludf.DUMMYFUNCTION("""COMPUTED_VALUE"""),"EIS") -> EIS | K8: =IFERROR(__xludf.DUMMYFUNCTION("""COMPUTED_VALUE"""),"8 Door TD") -> 8 Door TD | L8: =IFERROR(__xludf.DUMMYFUNCTION("""COMPUTED_VALUE"""),2.0) -> 2 | M8: =IFERROR(__xludf.DUMMYFUNCTION("""COMPUTED_VALUE"""),2.0) -> 2 | N8: =IFERROR(__xludf.DUMMYFUNCTION("IF(I8="""","""",IMAGE(QUERY('Deck Info'!A:F,""SELECT D WHERE A = '""&J8&""' AND B = '""&K8&""'"")))"),"") | O8: =IFERROR(__xludf.DUMMYFUNCTION("IF(I8="""","""",IMAGE(QUERY('Deck Info'!A:F,""SELECT E WHERE A = '""&J8&""' AND B = '""&K8&""'"")))"),"") | P8: =IFERROR(__xludf.DUMMYFUNCTION("IF(I8="""","""",IMAGE(QUERY('Deck Info'!A:F,""SELECT F WHERE A = '""&J8&""' AND B = '""&K8&""'"")))"),"") | V8: =IFERROR(__xludf.DUMMYFUNCTION("IF(Q8="""","""",IMAGE(QUERY('Deck Info'!A:F,""SELECT D WHERE A = '""&R8&""' AND B = '""&S8&""'"")))"),"") | W8: =IFERROR(__xludf.DUMMYFUNCTION("IF(Q8="""","""",IMAGE(QUERY('Deck Info'!A:F,""SELECT E WHERE A = '""&R8&""' AND B = '""&S8&""'"")))"),"") | X8: =IFERROR(__xludf.DUMMYFUNCTION("IF(Q8="""","""",IMAGE(QUERY('Deck Info'!A:F,""SELECT F WHERE A = '""&R8&""' AND B = '""&S8&""'"")))"),"") | AD8: =IFERROR(__xludf.DUMMYFUNCTION("IF(Y8="""","""",IMAGE(QUERY('Deck Info'!A:F,""SELECT D WHERE A = '""&Z8&""' AND B = '""&AA8&""'"")))"),"") | AE8: =IFERROR(__xludf.DUMMYFUNCTION("IF(Y8="""","""",IMAGE(QUERY('Deck Info'!A:F,""SELECT E WHERE A = '""&Z8&""' AND B = '""&AA8&""'"")))"),"") | AF8: =IFERROR(__xludf.DUMMYFUNCTION("IF(Y8="""","""",IMAGE(QUERY('Deck Info'!A:F,""SELECT F WHERE A = '""&Z8&""' AND B = '""&AA8&""'"")))"),"") | AL8: =IFERROR(__xludf.DUMMYFUNCTION("IF(AG8="""","""",IMAGE(QUERY('Deck Info'!A:F,""SELECT D WHERE A = '""&AH8&""' AND B = '""&AI8&""'"")))"),"") | AM8: =IFERROR(__xludf.DUMMYFUNCTION("IF(AG8="""","""",IMAGE(QUERY('Deck Info'!A:F,""SELECT E WHERE A = '""&AH8&""' AND B = '""&AI8&""'"")))"),"") | AN8: =IFERROR(__xludf.DUMMYFUNCTION("IF(AG8="""","""",IMAGE(QUERY('Deck Info'!A:F,""SELECT F WHERE A = '""&AH8&""' AND B = '""&AI8&""'"")))"),"")
A9: =IFERROR(__xludf.DUMMYFUNCTION("""COMPUTED_VALUE"""),"Kururu") -> Kururu | B9: =IFERROR(__xludf.DUMMYFUNCTION("""COMPUTED_VALUE"""),"MKI") -> MKI | C9: =IFERROR(__xludf.DUMMYFUNCTION("""COMPUTED_VALUE"""),"Standby Pants") -> Standby Pants | D9: =IFERROR(__xludf.DUMMYFUNCTION("""COMPUTED_VALUE"""),2.0) -> 2 | E9: =IFERROR(__xludf.DUMMYFUNCTION("""COMPUTED_VALUE"""),2.0) -> 2 | F9: =IFERROR(__xludf.DUMMYFUNCTION("IF(A9="""","""",IMAGE(QUERY('Deck Info'!A:F,""SELECT D WHERE A = '""&B9&""' AND B = '""&C9&""'"")))"),"") | G9: =IFERROR(__xludf.DUMMYFUNCTION("IF(A9="""","""",IMAGE(QUERY('Deck Info'!A:F,""SELECT E WHERE A = '""&B9&""' AND B = '""&C9&""'"")))"),"") | H9: =IFERROR(__xludf.DUMMYFUNCTION("IF(A9="""","""",IMAGE(QUERY('Deck Info'!A:F,""SELECT F WHERE A = '""&B9&""' AND B = '""&C9&""'"")))"),"") | I9: =IFERROR(__xludf.DUMMYFUNCTION("""COMPUTED_VALUE"""),"Will") -> Will | J9: =IFERROR(__xludf.DUMMYFUNCTION("""COMPUTED_VALUE"""),"LRC") -> LRC | K9: =IFERROR(__xludf.DUMMYFUNCTION("""COMPUTED_VALUE"""),"Pants Door") -> Pants Door | L9: =IFERROR(__xludf.DUMMYFUNCTION("""COMPUTED_VALUE"""),2.0) -> 2 | M9: =IFERROR(__xludf.DUMMYFUNCTION("""COMPUTED_VALUE"""),2.0) -> 2 | N9: =IFERROR(__xludf.DUMMYFUNCTION("IF(I9="""","""",IMAGE(QUERY('Deck Info'!A:F,""SELECT D WHERE A = '""&J9&""' AND B = '""&K9&""'"")))"),"") | O9: =IFERROR(__xludf.DUMMYFUNCTION("IF(I9="""","""",IMAGE(QUERY('Deck Info'!A:F,""SELECT E WHERE A = '""&J9&""' AND B = '""&K9&""'"")))"),"") | P9: =IFERROR(__xludf.DUMMYFUNCTION("IF(I9="""","""",IMAGE(QUERY('Deck Info'!A:F,""SELECT F WHERE A = '""&J9&""' AND B = '""&K9&""'"")))"),"") | V9: =IFERROR(__xludf.DUMMYFUNCTION("IF(Q9="""","""",IMAGE(QUERY('Deck Info'!A:F,""SELECT D WHERE A = '""&R9&""' AND B = '""&S9&""'"")))"),"") | W9: =IFERROR(__xludf.DUMMYFUNCTION("IF(Q9="""","""",IMAGE(QUERY('Deck Info'!A:F,""SELECT E WHERE A = '""&R9&""' AND B = '""&S9&""'"")))"),"") | X9: =IFERROR(__xludf.DUMMYFUNCTION("IF(Q9="""","""",IMAGE(QUERY('Deck Info'!A:F,""SELECT F WHERE A = '""&R9&""' AND B = '""&S9&""'"")))"),"") | AD9: =IFERROR(__xludf.DUMMYFUNCTION("IF(Y9="""","""",IMAGE(QUERY('Deck Info'!A:F,""SELECT D WHERE A = '""&Z9&""' AND B = '""&AA9&""'"")))"),"") | AE9: =IFERROR(__xludf.DUMMYFUNCTION("IF(Y9="""","""",IMAGE(QUERY('Deck Info'!A:F,""SELECT E WHERE A = '""&Z9&""' AND B = '""&AA9&""'"")))"),"") | AF9: =IFERROR(__xludf.DUMMYFUNCTION("IF(Y9="""","""",IMAGE(QUERY('Deck Info'!A:F,""SELECT F WHERE A = '""&Z9&""' AND B = '""&AA9&""'"")))"),"") | AL9: =IFERROR(__xludf.DUMMYFUNCTION("IF(AG9="""","""",IMAGE(QUERY('Deck Info'!A:F,""SELECT D WHERE A = '""&AH9&""' AND B = '""&AI9&""'"")))"),"") | AM9: =IFERROR(__xludf.DUMMYFUNCTION("IF(AG9="""","""",IMAGE(QUERY('Deck Info'!A:F,""SELECT E WHERE A = '""&AH9&""' AND B = '""&AI9&""'"")))"),"") | AN9: =IFERROR(__xludf.DUMMYFUNCTION("IF(AG9="""","""",IMAGE(QUERY('Deck Info'!A:F,""SELECT F WHERE A = '""&AH9&""' AND B = '""&AI9&""'"")))"),"")
